<?xml version="1.0"?>
<robot name="simple_arm">
    <material name="blue">
        <color rgba="0.0 0.0 1.0 1.0"/>
    </material>
    <material name="black">
        <color rgba="0.0 0.0 0.0 1.0"/>
    </material>
    <material name="white">
        <color rgba="1.0 1.0 1.0 1.0"/>
    </material>
    <material name="green">
        <color rgba="0.0 1.0 0.0 1.0"/>
    </material>
    <material name="red">
        <color rgba="1.0 0.0 0.0 1.0"/>
    </material>

    <link name="world"/>
    <link name="base_link">
        <visual>
            <origin xyz="0.0 0.0 0.05" rpy="0.0 0.0 0.0"/>
            <geometry>
                <cylinder length="0.1" radius="0.1"/>
            </geometry>
            <material name="black"/>
        </visual>
    </link>
    <joint name="base_joint" type="revolute">
        <origin xyz="0.0 0.0 0.0" rpy="0.0 0.0 0.0"/>
        <parent link="world"/>
        <child link="base_link"/>
        <axis xyz="0.0 0.0 1.0"/>
        <limit lower="-3.0" upper="3.0" effort="1000.0" velocity="1000.0"/>
    </joint>

    <link name="arm1">
        <visual>
            <origin xyz="0.0 0.0 0.25" rpy="0.0 0.0 0.0"/>
            <geometry>
                <cylinder length="0.5" radius="0.05"/>
            </geometry>
            <material name="white"/>
        </visual>
    </link>
    <joint name="arm1_joint" type="revolute">
        <origin xyz="0.0 0.0 0.1" rpy="0.0 0.0 0.0"/>
        <parent link="base_link"/>
        <child link="arm1"/>
        <axis xyz="1.0 0.0 0.0"/>
        <limit lower="-3.0" upper="3.0" effort="1000.0" velocity="1000.0"/>
    </joint>
    <link name="arm2">
        <visual>
            <origin xyz="0.0 0.0 0.25" rpy="0.0 0.0 0.0"/>
            <geometry>
                <cylinder length="0.5" radius="0.05"/>
            </geometry>
            <material name="blue"/>
        </visual>
    </link>
    <joint name="arm2_joint" type="revolute">
        <origin xyz="0.0 0.0 0.5" rpy="0.0 0.0 0.0"/>
        <parent link="arm1"/>
        <child link="arm2"/>
        <axis xyz="1.0 0.0 0.0"/>
        <limit lower="-3" upper="3.0" effort="1000.0" velocity="1000.0"/>
    </joint>
    <link name="wrist">
        <visual>
            <origin xyz="0.0 0.0 0.05" rpy="0.0 0.0 0.0"/>
            <geometry>
                <cylinder length="0.1" radius="0.03"/>
            </geometry>
            <material name="green"/>
        </visual>
    </link>
    <joint name="wrist_joint" type="revolute">
        <origin xyz="0.0 0.0 0.5" rpy="0.0 0.0 0.0"/>
        <parent link="arm2"/>
        <child link="wrist"/>
        <axis xyz="1.0 0.0 0.0"/>
        <limit lower="-3.0" upper="3.0" effort="1000.0" velocity="1000.0"/>
    </joint>
    <link name="hand">
        <visual>
            <origin xyz="0.0 0.0 0.025" rpy="0.0 0.0 0.0"/>
            <geometry>
                <box size="0.1 0.05 0.05"/>
            </geometry>
            <material name="red"/>
        </visual>
    </link>
    <joint name="hand_joint" type="revolute">
        <origin xyz="0.0 0.0 0.1" rpy="0.0 0.0 0.0"/>
        <parent link="wrist"/>
        <child link="hand"/>
        <axis xyz="0.0 0.0 1.0"/>
        <limit lower="-3.0" upper="3.0" effort="1000.0" velocity="1000.0"/>
    </joint>

</robot>